Traceback (most recent call last):
  File "/Volumes/workplace/personal/graupel-2/.venv/lib/python3.9/site-packages/jupyter_cache/executors/utils.py", line 51, in single_nb_execution
    executenb(
  File "/Volumes/workplace/personal/graupel-2/.venv/lib/python3.9/site-packages/nbclient/client.py", line 1112, in execute
    return NotebookClient(nb=nb, resources=resources, km=km, **kwargs).execute()
  File "/Volumes/workplace/personal/graupel-2/.venv/lib/python3.9/site-packages/nbclient/util.py", line 74, in wrapped
    return just_run(coro(*args, **kwargs))
  File "/Volumes/workplace/personal/graupel-2/.venv/lib/python3.9/site-packages/nbclient/util.py", line 53, in just_run
    return loop.run_until_complete(coro)
  File "/Users/jwwalker/.pyenv/versions/3.9.1/lib/python3.9/asyncio/base_events.py", line 642, in run_until_complete
    return future.result()
  File "/Volumes/workplace/personal/graupel-2/.venv/lib/python3.9/site-packages/nbclient/client.py", line 553, in async_execute
    await self.async_execute_cell(
  File "/Volumes/workplace/personal/graupel-2/.venv/lib/python3.9/site-packages/nbclient/client.py", line 857, in async_execute_cell
    self._check_raise_for_error(cell, exec_reply)
  File "/Volumes/workplace/personal/graupel-2/.venv/lib/python3.9/site-packages/nbclient/client.py", line 760, in _check_raise_for_error
    raise CellExecutionError.from_cell_and_msg(cell, exec_reply_content)
nbclient.exceptions.CellExecutionError: An error occurred while executing the following cell:
------------------
import types

foo = set()

def display_klv(klv, indent=0):
    foo.add(klv.key)
    if isinstance(klv.value, types.GeneratorType):
        for child in klv.value.__iter__():
            display_klv(child, indent+1)
    else:
        print((" " * indent) + f"{klv.key}: {klv.value}")
    
with open('/Users/jwwalker/Documents/Graupel-2/DCIM/100GOPRO/GX010093.bin', 'rb') as file:
    #stream = gpmf.io.extract_gpmf_stream(file)
    stream = file.read()
    for klv in gpmf.parse.iter_klv(stream):
        display_klv(klv)
        
display(foo)
------------------

[0;31m---------------------------------------------------------------------------[0m
[0;31mFileNotFoundError[0m                         Traceback (most recent call last)
[0;32m/var/folders/gw/fwbnxl652jx80ff49ndt1x6jzjvjfq/T/ipykernel_61345/569374030.py[0m in [0;36m<module>[0;34m[0m
[1;32m     11[0m         [0mprint[0m[0;34m([0m[0;34m([0m[0;34m" "[0m [0;34m*[0m [0mindent[0m[0;34m)[0m [0;34m+[0m [0;34mf"{klv.key}: {klv.value}"[0m[0;34m)[0m[0;34m[0m[0;34m[0m[0m
[1;32m     12[0m [0;34m[0m[0m
[0;32m---> 13[0;31m [0;32mwith[0m [0mopen[0m[0;34m([0m[0;34m'/Users/jwwalker/Documents/Graupel-2/DCIM/100GOPRO/GX010093.bin'[0m[0;34m,[0m [0;34m'rb'[0m[0;34m)[0m [0;32mas[0m [0mfile[0m[0;34m:[0m[0;34m[0m[0;34m[0m[0m
[0m[1;32m     14[0m     [0;31m#stream = gpmf.io.extract_gpmf_stream(file)[0m[0;34m[0m[0;34m[0m[0;34m[0m[0m
[1;32m     15[0m     [0mstream[0m [0;34m=[0m [0mfile[0m[0;34m.[0m[0mread[0m[0;34m([0m[0;34m)[0m[0;34m[0m[0;34m[0m[0m

[0;31mFileNotFoundError[0m: [Errno 2] No such file or directory: '/Users/jwwalker/Documents/Graupel-2/DCIM/100GOPRO/GX010093.bin'
FileNotFoundError: [Errno 2] No such file or directory: '/Users/jwwalker/Documents/Graupel-2/DCIM/100GOPRO/GX010093.bin'

